{
 "cells": [
  {
   "cell_type": "markdown",
   "metadata": {},
   "source": [
    "<h4>Writing like Shakespeare</h4>"
   ]
  },
  {
   "cell_type": "code",
   "execution_count": 67,
   "metadata": {},
   "outputs": [],
   "source": [
    "import io\n",
    "import sys\n",
    "\n",
    "import numpy as np\n",
    "\n",
    "import tensorflow as tf\n",
    "from tensorflow.keras.callbacks import LambdaCallback\n",
    "from tensorflow.keras.models import Model, load_model, Sequential\n",
    "from tensorflow.keras.layers import Dense, Activation, Dropout, Input, Masking\n",
    "from tensorflow.keras.layers import LSTM\n",
    "from tensorflow.keras.utils import get_file\n",
    "from tensorflow.keras.utils import pad_sequences"
   ]
  },
  {
   "cell_type": "code",
   "execution_count": 68,
   "metadata": {},
   "outputs": [],
   "source": [
    "def build_data(text, Tx=40, stride=3):\n",
    "    # input data will be the tokens from the real poems\n",
    "    X = []\n",
    "    # labels will be the next character that should come\n",
    "    Y = []\n",
    "    for i in range(0, len(text)-Tx, stride):\n",
    "        X.append(text[i : i + Tx])\n",
    "        Y.append(text[i + Tx])\n",
    "    return X, Y\n",
    "\n",
    "\n",
    "def on_epoch_end(epoch, logs):\n",
    "    None\n",
    "\n",
    "def vectorization(X, Y, n_x, char_indices, Tx=40):\n",
    "    m = len(X)\n",
    "    x = np.zeros((m, Tx, n_x), dtype=bool)\n",
    "    y = np.zeros((m, Tx), dtype=bool)\n",
    "\n",
    "    for i, sentence in enumerate(X):\n",
    "        for j, char in enumerate(sentence):\n",
    "            x[i, j, char_indices[char]] = 1\n",
    "        y[i, char_indices[Y[i]]] = 1\n",
    "\n",
    "    return x, y"
   ]
  },
  {
   "cell_type": "code",
   "execution_count": 69,
   "metadata": {},
   "outputs": [
    {
     "name": "stdout",
     "output_type": "stream",
     "text": [
      "Loading text data...\n",
      "Creating training set...\n",
      "Vectorizing training set...\n",
      "WARNING:tensorflow:Layer lstm_5 will not use cuDNN kernels since it doesn't meet the criteria. It will use a generic GPU kernel as fallback when running on GPU.\n",
      "WARNING:tensorflow:Layer lstm_6 will not use cuDNN kernels since it doesn't meet the criteria. It will use a generic GPU kernel as fallback when running on GPU.\n"
     ]
    }
   ],
   "source": [
    "print('Loading text data...')\n",
    "text = open(\"shakespeare.txt\", \"r\").read().lower()\n",
    "Tx = 40\n",
    "chars = sorted(list(set(text)))\n",
    "char_indices = dict((c, i) for i, c in enumerate(chars))\n",
    "indices_char = dict((i, c) for i, c in enumerate(chars))\n",
    "\n",
    "print(\"Creating training set...\")\n",
    "X, Y = build_data(text, Tx, stride=3)\n",
    "\n",
    "print('Vectorizing training set...')\n",
    "x, y = vectorization(X, Y, n_x=len(chars), char_indices=char_indices)\n",
    "model = load_model('models/model_shakespeare_kiank_350_epoch.h5')"
   ]
  },
  {
   "cell_type": "code",
   "execution_count": 70,
   "metadata": {},
   "outputs": [
    {
     "ename": "ValueError",
     "evalue": "in user code:\n\n    File \"/home/str/.local/lib/python3.10/site-packages/keras/src/engine/training.py\", line 1401, in train_function  *\n        return step_function(self, iterator)\n    File \"/home/str/.local/lib/python3.10/site-packages/keras/src/engine/training.py\", line 1384, in step_function  **\n        outputs = model.distribute_strategy.run(run_step, args=(data,))\n    File \"/home/str/.local/lib/python3.10/site-packages/keras/src/engine/training.py\", line 1373, in run_step  **\n        outputs = model.train_step(data)\n    File \"/home/str/.local/lib/python3.10/site-packages/keras/src/engine/training.py\", line 1150, in train_step\n        y_pred = self(x, training=True)\n    File \"/home/str/.local/lib/python3.10/site-packages/keras/src/utils/traceback_utils.py\", line 70, in error_handler\n        raise e.with_traceback(filtered_tb) from None\n    File \"/home/str/.local/lib/python3.10/site-packages/keras/src/engine/input_spec.py\", line 298, in assert_input_compatibility\n        raise ValueError(\n\n    ValueError: Input 0 of layer \"model_1\" is incompatible with the layer: expected shape=(None, 40, 38), found shape=(None, 40, 36)\n",
     "output_type": "error",
     "traceback": [
      "\u001b[0;31m---------------------------------------------------------------------------\u001b[0m",
      "\u001b[0;31mValueError\u001b[0m                                Traceback (most recent call last)",
      "Cell \u001b[0;32mIn[70], line 3\u001b[0m\n\u001b[1;32m      1\u001b[0m print_callback \u001b[38;5;241m=\u001b[39m LambdaCallback(on_epoch_end\u001b[38;5;241m=\u001b[39mon_epoch_end)\n\u001b[0;32m----> 3\u001b[0m \u001b[43mmodel\u001b[49m\u001b[38;5;241;43m.\u001b[39;49m\u001b[43mfit\u001b[49m\u001b[43m(\u001b[49m\u001b[43mx\u001b[49m\u001b[43m,\u001b[49m\u001b[43m \u001b[49m\u001b[43my\u001b[49m\u001b[43m,\u001b[49m\u001b[43m \u001b[49m\u001b[43mbatch_size\u001b[49m\u001b[38;5;241;43m=\u001b[39;49m\u001b[38;5;241;43m64\u001b[39;49m\u001b[43m,\u001b[49m\u001b[43m \u001b[49m\u001b[43mepochs\u001b[49m\u001b[38;5;241;43m=\u001b[39;49m\u001b[38;5;241;43m1\u001b[39;49m\u001b[43m,\u001b[49m\u001b[43m \u001b[49m\u001b[43mcallbacks\u001b[49m\u001b[38;5;241;43m=\u001b[39;49m\u001b[43m[\u001b[49m\u001b[43mprint_callback\u001b[49m\u001b[43m]\u001b[49m\u001b[43m)\u001b[49m\n",
      "File \u001b[0;32m~/.local/lib/python3.10/site-packages/keras/src/utils/traceback_utils.py:70\u001b[0m, in \u001b[0;36mfilter_traceback.<locals>.error_handler\u001b[0;34m(*args, **kwargs)\u001b[0m\n\u001b[1;32m     67\u001b[0m     filtered_tb \u001b[38;5;241m=\u001b[39m _process_traceback_frames(e\u001b[38;5;241m.\u001b[39m__traceback__)\n\u001b[1;32m     68\u001b[0m     \u001b[38;5;66;03m# To get the full stack trace, call:\u001b[39;00m\n\u001b[1;32m     69\u001b[0m     \u001b[38;5;66;03m# `tf.debugging.disable_traceback_filtering()`\u001b[39;00m\n\u001b[0;32m---> 70\u001b[0m     \u001b[38;5;28;01mraise\u001b[39;00m e\u001b[38;5;241m.\u001b[39mwith_traceback(filtered_tb) \u001b[38;5;28;01mfrom\u001b[39;00m \u001b[38;5;28;01mNone\u001b[39;00m\n\u001b[1;32m     71\u001b[0m \u001b[38;5;28;01mfinally\u001b[39;00m:\n\u001b[1;32m     72\u001b[0m     \u001b[38;5;28;01mdel\u001b[39;00m filtered_tb\n",
      "File \u001b[0;32m/tmp/__autograph_generated_filex4vw4rec.py:15\u001b[0m, in \u001b[0;36mouter_factory.<locals>.inner_factory.<locals>.tf__train_function\u001b[0;34m(iterator)\u001b[0m\n\u001b[1;32m     13\u001b[0m \u001b[38;5;28;01mtry\u001b[39;00m:\n\u001b[1;32m     14\u001b[0m     do_return \u001b[38;5;241m=\u001b[39m \u001b[38;5;28;01mTrue\u001b[39;00m\n\u001b[0;32m---> 15\u001b[0m     retval_ \u001b[38;5;241m=\u001b[39m ag__\u001b[38;5;241m.\u001b[39mconverted_call(ag__\u001b[38;5;241m.\u001b[39mld(step_function), (ag__\u001b[38;5;241m.\u001b[39mld(\u001b[38;5;28mself\u001b[39m), ag__\u001b[38;5;241m.\u001b[39mld(iterator)), \u001b[38;5;28;01mNone\u001b[39;00m, fscope)\n\u001b[1;32m     16\u001b[0m \u001b[38;5;28;01mexcept\u001b[39;00m:\n\u001b[1;32m     17\u001b[0m     do_return \u001b[38;5;241m=\u001b[39m \u001b[38;5;28;01mFalse\u001b[39;00m\n",
      "\u001b[0;31mValueError\u001b[0m: in user code:\n\n    File \"/home/str/.local/lib/python3.10/site-packages/keras/src/engine/training.py\", line 1401, in train_function  *\n        return step_function(self, iterator)\n    File \"/home/str/.local/lib/python3.10/site-packages/keras/src/engine/training.py\", line 1384, in step_function  **\n        outputs = model.distribute_strategy.run(run_step, args=(data,))\n    File \"/home/str/.local/lib/python3.10/site-packages/keras/src/engine/training.py\", line 1373, in run_step  **\n        outputs = model.train_step(data)\n    File \"/home/str/.local/lib/python3.10/site-packages/keras/src/engine/training.py\", line 1150, in train_step\n        y_pred = self(x, training=True)\n    File \"/home/str/.local/lib/python3.10/site-packages/keras/src/utils/traceback_utils.py\", line 70, in error_handler\n        raise e.with_traceback(filtered_tb) from None\n    File \"/home/str/.local/lib/python3.10/site-packages/keras/src/engine/input_spec.py\", line 298, in assert_input_compatibility\n        raise ValueError(\n\n    ValueError: Input 0 of layer \"model_1\" is incompatible with the layer: expected shape=(None, 40, 38), found shape=(None, 40, 36)\n"
     ]
    }
   ],
   "source": [
    "print_callback = LambdaCallback(on_epoch_end=on_epoch_end)\n",
    "\n",
    "model.fit(x, y, batch_size=64, epochs=1, callbacks=[print_callback])"
   ]
  }
 ],
 "metadata": {
  "kernelspec": {
   "display_name": "Python 3 (ipykernel)",
   "language": "python",
   "name": "python3"
  },
  "language_info": {
   "codemirror_mode": {
    "name": "ipython",
    "version": 3
   },
   "file_extension": ".py",
   "mimetype": "text/x-python",
   "name": "python",
   "nbconvert_exporter": "python",
   "pygments_lexer": "ipython3",
   "version": "3.10.12"
  }
 },
 "nbformat": 4,
 "nbformat_minor": 2
}
